Workbook

Sheet Sheet1
A1: PORT CODE | B1: DATE | C1: IEC | D1: HS CODE | E1: GOODS DESCRIPTION | F1: Master category | G1: Model Name | H1: Model Number | I1: Capacity | J1: Qty | K1: Unit of measure | L1: Price | M1: Unit of measure | N1: QUANTITY | O1: UNIT | P1: UNIT PRICE_INR | Q1: TOTAL VALUE_INR | R1: UNIT PRICE_USD | S1: TOTAL VALUE_USD | T1: DUTY PAID_INR
A2: INNSA1 | B2: 2025-10-28 | C2: 0301049751 | D2: 73239990 | E2: TH5170 STEEL CUTLERY HOLDER (QTY:600 PCS/USD 2.03 PER PCS) TH5170 STEEL CUTLERY HOLDER (QTY:600 PCS/USD 2.03 PER PCS) | N2: 290 | O2: KGS | P2: 401.72531 | Q2: 116500.34 | R2: 4.5290339 | S2: 1313.4198 | T2: 32736.6
A3: INNSA1 | B3: 2025-10-28 | C3: 0301049751 | D3: 73231000 | E3: 8001-2 STEEL SCRUBBER 2PCS SET (QTY: 336000 SETS/USD 0.139 PER SETS)8001-2 STEEL SCRUBBER 2PCS SET (QTY: 336000 SETS/USD 0.139 P | N3: 9800 | O3: KGS | P3: 440.60222 | Q3: 4317901.7 | R3: 4.9673305 | S3: 48679.839 | T3: 1898149.5
A4: INNSA1 | B4: 2025-10-23 | C4: 0301049751 | D4: 73239990 | E4: MILD STEEL MULTI FUNCTION CLOTH STAND (RYX-02-020) (QTY: 1,232 PCS/CNY:101 PER PCS)MILD STEEL MULTI FUNCTION CLOTH STAND (RYX-02-020) (QTY: 1,2 | N4: 4004 | O4: KGS | P4: 408.89366 | Q4: 1637210.2 | R4: 4.6098496 | S4: 18457.838 | T4: 460056
A5: INNSA1 | B5: 2025-10-13 | C5: 0301049751 | D5: 73239990 | E5: SB-12 STEEL TEA STRAINER BIG (QTY 6336 PCS/USD 0.973 PER PCS)SB-12 STEEL TEA STRAINER BIG (QTY 6336 PCS/USD 0.973 PER PCS | N5: 1548.8 | O5: KGS | P5: 378.45784 | Q5: 586155.51 | R5: 4.219151 | S5: 6534.6211 | T5: 164709.7
A6: INNSA1 | B6: 2025-10-13 | C6: 0301049751 | D6: 73239990 | E6: SB-12 STEEL TEA STRAINER BIG (QTY 43038 PCS/USD 0.9718 PER PCS)SB-12 STEEL TEA STRAINER BIG (QTY 43038 PCS/USD 0.9718 PER P | N6: 10042.2 | O6: KGS | P6: 399.73967 | Q6: 4014265.8 | R6: 4.4564066 | S6: 44752.127 | T6: 1128008.7
A7: INNSA1 | B7: 2025-10-08 | C7: 0301049751 | D7: 73239990 | E7: STEEL HANGER WITH HOOK (SL-89) (QTY:70056 PCS/CNY:7.45 PER PCS)STEEL HANGER WITH HOOK (SL-89) (QTY:70056 PCS/:7.45 | N7: 15568 | O7: KGS | P7: 432.15818 | Q7: 6727838.5 | R7: 4.8178169 | S7: 75003.774 | T7: 1890522.7
A8: INNSA1 | B8: 2025-10-06 | C8: 0301049751 | D8: 73239990 | E8: STEEL HANGER 10PCS SET (AM-969) (QTY: 480 SET/USD 0.819 PERSET)STEEL HANGER 10PCS SET (AM-969) (QTY: 480 SET/USD 0.819 PER | N8: 380 | O8: KGS | P8: 100.44208 | Q8: 38167.99 | R8: 1.1197556 | S8: 425.50713 | T8: 10725.3
A9: INNSA1 | B9: 2025-10-01 | C9: 0301049751 | D9: 73239990 | E9: AM-967 STEEL FRUIT BASKET (QTY 400 PCS/USD 1.031 PER PCS) AM-967 STEEL FRUIT BASKET (QTY 400 PCS/USD 1.031 PER PCS) | N9: 460 | O9: KGS | P9: 85.377826 | Q9: 39273.8 | R9: 0.96092095 | S9: 442.02364 | T9: 11036
A10: INNSA1 | B10: 2025-10-01 | C10: 0301049751 | D10: 73239990 | E10: AM-966 STEEL FRUIT BASKET (QTY 400 PCS/USD 1.017 PER PCS) AM-966 STEEL FRUIT BASKET (QTY 400 PCS/USD 1.017 PER PCS) | N10: 310 | O10: KGS | P10: 124.96932 | Q10: 38740.49 | R10: 1.4065202 | S10: 436.02127 | T10: 10886.1
A11: INNSA1 | B11: 2025-10-01 | C11: 0301049751 | D11: 73239990 | E11: AM-965 STEEL SPOON & FORK HOLDER (QTY 480 PCS/USD 0.734 PERPCS)AM-965 STEEL SPOON & FORK HOLDER (QTY 480 PCS/USD 0.734 PER | N11: 168 | O11: KGS | P11: 199.71571 | Q11: 33552.24 | R11: 2.2477852 | S11: 377.62791 | T11: 9428.1
A12: INNSA1 | B12: 2025-10-01 | C12: 0301049751 | D12: 73231000 | E12: 8001-2 STEEL SCRUBBER 2 PCS SET (QTY 336000 SETS/USD 0.139 PER SETS)8001-2 STEEL SCRUBBER 2 PCS SET (QTY 336000 SETS/USD 0.139 P | N12: 9800 | O12: KGS | P12: 456.12539 | Q12: 4470028.8 | R12: 5.1336566 | S12: 50309.835 | T12: 1965024.7
A13: INNSA1 | B13: 2025-09-27 | C13: 0301049751 | D13: 73231000 | E13: OKS-4156 STEEL SCRUBBER 6PCS SET (QTY: 93360 PCS /USD 0.228PER PCS)OKS-4156 STEEL SCRUBBER 6PCS SET (QTY: 93360 PCS /USD 0.228 | N13: 7496.03 | O13: KGS | P13: 263.57138 | Q13: 1975739 | R13: 2.9664758 | S13: 22236.792 | T13: 868534.9
... A2080: INNSA1 | B2080: 2017-01-13 | C2080: 0301049751 | D2080: 73239990 | E2080: STAINLESS STEEL SPORTS BOTTLE 750ML S-308-C6-NP-20(TOTAL NET WT.284.83 KGS) | N2080: 1656 | O2080: PCS | P2080: 79.149233 | Q2080: 131071.13 | R2080: 1.1504249 | S2080: 1905.1036 | T2080: 22410.6

Sheet Raw Data
A1: PORT CODE | B1: DATE | C1: IEC | D1: HS CODE | E1: GOODS DESCRIPTION | F1: Master category | G1: Model Name | H1: Model Number | I1: Capacity | J1: Qty | K1: Unit of measure | L1: Price | M1: Unit of measure2 | N1: QUANTITY | O1: UNIT | P1: UNIT PRICE_INR | Q1: TOTAL VALUE_INR | R1: UNIT PRICE_USD | S1: TOTAL VALUE_USD | T1: DUTY PAID_INR
A2: INNSA1 | B2: 2025-10-28 | C2: 0301049751 | D2: 73239990 | E2: TH5170 STEEL CUTLERY HOLDER (QTY:600 PCS/USD 2.03 PER PCS) TH5170 STEEL CUTLERY HOLDER (QTY:600 PCS/USD 2.03 PER PCS) | F2: =IFERROR(TRIM(LEFT(E2, FIND(" ", E2)-1)), "") -> TH5170 | G2: =IFERROR(TRIM(MID(E2, FIND(" ", E2)+1, FIND("(",E2)-FIND(" ",E2)-1)), "") -> STEEL CUTLERY HOLDER | H2: =IFERROR(MID(E2, FIND("(",E2)+1, FIND(")",E2)-FIND("(",E2)-1), "") -> QTY:600 PCS/USD 2.03 PER PCS | I2: =IFERROR(MID(E2, FIND("(",E2, FIND("P",E2)) + 1, FIND(" ",E2, FIND("(",E2)) - FIND("(",E2) - 1), "") -> QTY:600 | J2: =IFERROR(--SUBSTITUTE(MID(E2, FIND("QTY", E2)+4, FIND(" ",E2, FIND("QTY",E2)+5)-FIND("QTY",E2)-4), ",",""),"") -> 600 | K2: =IFERROR( TRIM(_xlfn.TEXTAFTER(_xlfn.TEXTBEFORE(_xlfn.TEXTAFTER(tblRaw[[#This Row],[GOODS DESCRIPTION]],"QTY"),"/")," ")), tblRaw[[#This Row],[Unit of measure]] ) -> PCS | L2: =IFERROR(--MID(E2, FIND("USD",E2)+4, FIND(" ",E2,FIND("USD",E2)+5)-FIND("USD",E2)-4), IFERROR(--MID(E2,FIND("CNY",E2)+4,FIND(" ",E2,FIND("CNY",E2)+5)-FIND("CNY",E2)-4),"")) -> 2.03 | M2: =IFERROR(IF(ISNUMBER(SEARCH("USD",E2)),"USD",IF(ISNUMBER(SEARCH("CNY",E2)),"CNY","")), "") -> USD | N2: 290 | O2: KGS | P2: 401.72531 | Q2: 116500.34 | R2: 4.5290339 | S2: 1313.4198 | T2: 32736.6 | AP2: GOODS DESCRIPTION
A3: INNSA1 | B3: 2025-10-28 | C3: 0301049751 | D3: 73231000 | E3: 8001-2 STEEL SCRUBBER 2PCS SET (QTY: 336000 SETS/USD 0.139 PER SETS)8001-2 STEEL SCRUBBER 2PCS SET (QTY: 336000 SETS/USD 0.139 P | F3: =IFERROR(TRIM(LEFT(E3, FIND(" ", E3)-1)), "") -> 8001-2 | G3: =IFERROR(TRIM(MID(E3, FIND(" ", E3)+1, FIND("(",E3)-FIND(" ",E3)-1)), "") -> STEEL SCRUBBER 2PCS SET | H3: =IFERROR(MID(E3, FIND("(",E3)+1, FIND(")",E3)-FIND("(",E3)-1), "") -> QTY: 336000 SETS/USD 0.139 PER SETS | I3: =IFERROR(MID(E3, FIND("(",E3, FIND("P",E3)) + 1, FIND(" ",E3, FIND("(",E3)) - FIND("(",E3) - 1), "") -> QTY: | J3: =IFERROR(--SUBSTITUTE(MID(E3, FIND("QTY", E3)+4, FIND(" ",E3, FIND("QTY",E3)+5)-FIND("QTY",E3)-4), ",",""),"") -> 336000 | K3: =IFERROR( TRIM(_xlfn.TEXTAFTER(_xlfn.TEXTBEFORE(_xlfn.TEXTAFTER(tblRaw[[#This Row],[GOODS DESCRIPTION]],"QTY"),"/")," ")), tblRaw[[#This Row],[Unit of measure]] ) -> 336000 SETS | L3: =IFERROR(--MID(E3, FIND("USD",E3)+4, FIND(" ",E3,FIND("USD",E3)+5)-FIND("USD",E3)-4), IFERROR(--MID(E3,FIND("CNY",E3)+4,FIND(" ",E3,FIND("CNY",E3)+5)-FIND("CNY",E3)-4),"")) -> 0.139 | M3: =IFERROR(IF(ISNUMBER(SEARCH("USD",E3)),"USD",IF(ISNUMBER(SEARCH("CNY",E3)),"CNY","")), "") -> USD | N3: 9800 | O3: KGS | P3: 440.60222 | Q3: 4317901.7 | R3: 4.9673305 | S3: 48679.839 | T3: 1898149.5
A4: INNSA1 | B4: 2025-10-23 | C4: 0301049751 | D4: 73239990 | E4: MILD STEEL MULTI FUNCTION CLOTH STAND (RYX-02-020) (QTY: 1,232 PCS/CNY:101 PER PCS)MILD STEEL MULTI FUNCTION CLOTH STAND (RYX-02-020) (QTY: 1,2 | F4: =IFERROR(TRIM(LEFT(E4, FIND(" ", E4)-1)), "") -> MILD | G4: =IFERROR(TRIM(MID(E4, FIND(" ", E4)+1, FIND("(",E4)-FIND(" ",E4)-1)), "") -> STEEL MULTI FUNCTION CLOTH STAND | H4: =IFERROR(MID(E4, FIND("(",E4)+1, FIND(")",E4)-FIND("(",E4)-1), "") -> RYX-02-020 | I4: =IFERROR(MID(E4, FIND("(",E4, FIND("P",E4)) + 1, FIND(" ",E4, FIND("(",E4)) - FIND("(",E4) - 1), "") -> RYX-02-020) | J4: =IFERROR(--SUBSTITUTE(MID(E4, FIND("QTY", E4)+4, FIND(" ",E4, FIND("QTY",E4)+5)-FIND("QTY",E4)-4), ",",""),"") -> 1232 | K4: =IFERROR( TRIM(_xlfn.TEXTAFTER(_xlfn.TEXTBEFORE(_xlfn.TEXTAFTER(tblRaw[[#This Row],[GOODS DESCRIPTION]],"QTY"),"/")," ")), tblRaw[[#This Row],[Unit of measure]] ) -> 1,232 PCS | L4: =IFERROR(--MID(E4, FIND("USD",E4)+4, FIND(" ",E4,FIND("USD",E4)+5)-FIND("USD",E4)-4), IFERROR(--MID(E4,FIND("CNY",E4)+4,FIND(" ",E4,FIND("CNY",E4)+5)-FIND("CNY",E4)-4),"")) -> 101 | M4: =IFERROR(IF(ISNUMBER(SEARCH("USD",E4)),"USD",IF(ISNUMBER(SEARCH("CNY",E4)),"CNY","")), "") -> CNY | N4: 4004 | O4: KGS | P4: 408.89366 | Q4: 1637210.2 | R4: 4.6098496 | S4: 18457.838 | T4: 460056
A5: INNSA1 | B5: 2025-10-13 | C5: 0301049751 | D5: 73239990 | E5: SB-12 STEEL TEA STRAINER BIG (QTY 6336 PCS/USD 0.973 PER PCS)SB-12 STEEL TEA STRAINER BIG (QTY 6336 PCS/USD 0.973 PER PCS | F5: =IFERROR(TRIM(LEFT(E5, FIND(" ", E5)-1)), "") -> SB-12 | G5: =IFERROR(TRIM(MID(E5, FIND(" ", E5)+1, FIND("(",E5)-FIND(" ",E5)-1)), "") -> STEEL TEA STRAINER BIG | H5: =IFERROR(MID(E5, FIND("(",E5)+1, FIND(")",E5)-FIND("(",E5)-1), "") -> QTY 6336 PCS/USD 0.973 PER PCS | I5: =IFERROR(MID(E5, FIND("(",E5, FIND("P",E5)) + 1, FIND(" ",E5, FIND("(",E5)) - FIND("(",E5) - 1), "") -> QTY | J5: =IFERROR(--SUBSTITUTE(MID(E5, FIND("QTY", E5)+4, FIND(" ",E5, FIND("QTY",E5)+5)-FIND("QTY",E5)-4), ",",""),"") -> 6336 | K5: =IFERROR( TRIM(_xlfn.TEXTAFTER(_xlfn.TEXTBEFORE(_xlfn.TEXTAFTER(tblRaw[[#This Row],[GOODS DESCRIPTION]],"QTY"),"/")," ")), tblRaw[[#This Row],[Unit of measure]] ) -> 6336 PCS | L5: =IFERROR(--MID(E5, FIND("USD",E5)+4, FIND(" ",E5,FIND("USD",E5)+5)-FIND("USD",E5)-4), IFERROR(--MID(E5,FIND("CNY",E5)+4,FIND(" ",E5,FIND("CNY",E5)+5)-FIND("CNY",E5)-4),"")) -> 0.973 | M5: =IFERROR(IF(ISNUMBER(SEARCH("USD",E5)),"USD",IF(ISNUMBER(SEARCH("CNY",E5)),"CNY","")), "") -> USD | N5: 1548.8 | O5: KGS | P5: 378.45784 | Q5: 586155.51 | R5: 4.219151 | S5: 6534.6211 | T5: 164709.7
A6: INNSA1 | B6: 2025-10-13 | C6: 0301049751 | D6: 73239990 | E6: SB-12 STEEL TEA STRAINER BIG (QTY 43038 PCS/USD 0.9718 PER PCS)SB-12 STEEL TEA STRAINER BIG (QTY 43038 PCS/USD 0.9718 PER P | F6: =IFERROR(TRIM(LEFT(E6, FIND(" ", E6)-1)), "") -> SB-12 | G6: =IFERROR(TRIM(MID(E6, FIND(" ", E6)+1, FIND("(",E6)-FIND(" ",E6)-1)), "") -> STEEL TEA STRAINER BIG | H6: =IFERROR(MID(E6, FIND("(",E6)+1, FIND(")",E6)-FIND("(",E6)-1), "") -> QTY 43038 PCS/USD 0.9718 PER PCS | I6: =IFERROR(MID(E6, FIND("(",E6, FIND("P",E6)) + 1, FIND(" ",E6, FIND("(",E6)) - FIND("(",E6) - 1), "") -> QTY | J6: =IFERROR(--SUBSTITUTE(MID(E6, FIND("QTY", E6)+4, FIND(" ",E6, FIND("QTY",E6)+5)-FIND("QTY",E6)-4), ",",""),"") -> 43038 | K6: =IFERROR( TRIM(_xlfn.TEXTAFTER(_xlfn.TEXTBEFORE(_xlfn.TEXTAFTER(tblRaw[[#This Row],[GOODS DESCRIPTION]],"QTY"),"/")," ")), tblRaw[[#This Row],[Unit of measure]] ) -> 43038 PCS | L6: =IFERROR(--MID(E6, FIND("USD",E6)+4, FIND(" ",E6,FIND("USD",E6)+5)-FIND("USD",E6)-4), IFERROR(--MID(E6,FIND("CNY",E6)+4,FIND(" ",E6,FIND("CNY",E6)+5)-FIND("CNY",E6)-4),"")) -> 0.9718 | M6: =IFERROR(IF(ISNUMBER(SEARCH("USD",E6)),"USD",IF(ISNUMBER(SEARCH("CNY",E6)),"CNY","")), "") -> USD | N6: 10042.2 | O6: KGS | P6: 399.73967 | Q6: 4014265.8 | R6: 4.4564066 | S6: 44752.127 | T6: 1128008.7
A7: INNSA1 | B7: 2025-10-08 | C7: 0301049751 | D7: 73239990 | E7: STEEL HANGER WITH HOOK (SL-89) (QTY:70056 PCS/CNY:7.45 PER PCS)STEEL HANGER WITH HOOK (SL-89) (QTY:70056 PCS/:7.45 | F7: =IFERROR(TRIM(LEFT(E7, FIND(" ", E7)-1)), "") -> STEEL | G7: =IFERROR(TRIM(MID(E7, FIND(" ", E7)+1, FIND("(",E7)-FIND(" ",E7)-1)), "") -> HANGER WITH HOOK | H7: =IFERROR(MID(E7, FIND("(",E7)+1, FIND(")",E7)-FIND("(",E7)-1), "") -> SL-89 | I7: =IFERROR(MID(E7, FIND("(",E7, FIND("P",E7)) + 1, FIND(" ",E7, FIND("(",E7)) - FIND("(",E7) - 1), "") -> SL-89) | J7: =IFERROR(--SUBSTITUTE(MID(E7, FIND("QTY", E7)+4, FIND(" ",E7, FIND("QTY",E7)+5)-FIND("QTY",E7)-4), ",",""),"") -> 70056 | K7: =IFERROR( TRIM(_xlfn.TEXTAFTER(_xlfn.TEXTBEFORE(_xlfn.TEXTAFTER(tblRaw[[#This Row],[GOODS DESCRIPTION]],"QTY"),"/")," ")), tblRaw[[#This Row],[Unit of measure]] ) -> PCS | L7: =IFERROR(--MID(E7, FIND("USD",E7)+4, FIND(" ",E7,FIND("USD",E7)+5)-FIND("USD",E7)-4), IFERROR(--MID(E7,FIND("CNY",E7)+4,FIND(" ",E7,FIND("CNY",E7)+5)-FIND("CNY",E7)-4),"")) -> 7.45 | M7: =IFERROR(IF(ISNUMBER(SEARCH("USD",E7)),"USD",IF(ISNUMBER(SEARCH("CNY",E7)),"CNY","")), "") -> CNY | N7: 15568 | O7: KGS | P7: 432.15818 | Q7: 6727838.5 | R7: 4.8178169 | S7: 75003.774 | T7: 1890522.7
A8: INNSA1 | B8: 2025-10-06 | C8: 0301049751 | D8: 73239990 | E8: STEEL HANGER 10PCS SET (AM-969) (QTY: 480 SET/USD 0.819 PERSET)STEEL HANGER 10PCS SET (AM-969) (QTY: 480 SET/USD 0.819 PER | F8: =IFERROR(TRIM(LEFT(E8, FIND(" ", E8)-1)), "") -> STEEL | G8: =IFERROR(TRIM(MID(E8, FIND(" ", E8)+1, FIND("(",E8)-FIND(" ",E8)-1)), "") -> HANGER 10PCS SET | H8: =IFERROR(MID(E8, FIND("(",E8)+1, FIND(")",E8)-FIND("(",E8)-1), "") -> AM-969 | I8: =IFERROR(MID(E8, FIND("(",E8, FIND("P",E8)) + 1, FIND(" ",E8, FIND("(",E8)) - FIND("(",E8) - 1), "") -> AM-969) | J8: =IFERROR(--SUBSTITUTE(MID(E8, FIND("QTY", E8)+4, FIND(" ",E8, FIND("QTY",E8)+5)-FIND("QTY",E8)-4), ",",""),"") -> 480 | K8: =IFERROR( TRIM(_xlfn.TEXTAFTER(_xlfn.TEXTBEFORE(_xlfn.TEXTAFTER(tblRaw[[#This Row],[GOODS DESCRIPTION]],"QTY"),"/")," ")), tblRaw[[#This Row],[Unit of measure]] ) -> 480 SET | L8: =IFERROR(--MID(E8, FIND("USD",E8)+4, FIND(" ",E8,FIND("USD",E8)+5)-FIND("USD",E8)-4), IFERROR(--MID(E8,FIND("CNY",E8)+4,FIND(" ",E8,FIND("CNY",E8)+5)-FIND("CNY",E8)-4),"")) -> 0.819 | M8: =IFERROR(IF(ISNUMBER(SEARCH("USD",E8)),"USD",IF(ISNUMBER(SEARCH("CNY",E8)),"CNY","")), "") -> USD | N8: 380 | O8: KGS | P8: 100.44208 | Q8: 38167.99 | R8: 1.1197556 | S8: 425.50713 | T8: 10725.3
A9: INNSA1 | B9: 2025-10-01 | C9: 0301049751 | D9: 73239990 | E9: AM-967 STEEL FRUIT BASKET (QTY 400 PCS/USD 1.031 PER PCS) AM-967 STEEL FRUIT BASKET (QTY 400 PCS/USD 1.031 PER PCS) | F9: =IFERROR(TRIM(LEFT(E9, FIND(" ", E9)-1)), "") -> AM-967 | G9: =IFERROR(TRIM(MID(E9, FIND(" ", E9)+1, FIND("(",E9)-FIND(" ",E9)-1)), "") -> STEEL FRUIT BASKET | H9: =IFERROR(MID(E9, FIND("(",E9)+1, FIND(")",E9)-FIND("(",E9)-1), "") -> QTY 400 PCS/USD 1.031 PER PCS | I9: =IFERROR(MID(E9, FIND("(",E9, FIND("P",E9)) + 1, FIND(" ",E9, FIND("(",E9)) - FIND("(",E9) - 1), "") -> QTY | J9: =IFERROR(--SUBSTITUTE(MID(E9, FIND("QTY", E9)+4, FIND(" ",E9, FIND("QTY",E9)+5)-FIND("QTY",E9)-4), ",",""),"") -> 400 | K9: =IFERROR( TRIM(_xlfn.TEXTAFTER(_xlfn.TEXTBEFORE(_xlfn.TEXTAFTER(tblRaw[[#This Row],[GOODS DESCRIPTION]],"QTY"),"/")," ")), tblRaw[[#This Row],[Unit of measure]] ) -> 400 PCS | L9: =IFERROR(--MID(E9, FIND("USD",E9)+4, FIND(" ",E9,FIND("USD",E9)+5)-FIND("USD",E9)-4), IFERROR(--MID(E9,FIND("CNY",E9)+4,FIND(" ",E9,FIND("CNY",E9)+5)-FIND("CNY",E9)-4),"")) -> 1.031 | M9: =IFERROR(IF(ISNUMBER(SEARCH("USD",E9)),"USD",IF(ISNUMBER(SEARCH("CNY",E9)),"CNY","")), "") -> USD | N9: 460 | O9: KGS | P9: 85.377826 | Q9: 39273.8 | R9: 0.96092095 | S9: 442.02364 | T9: 11036
A10: INNSA1 | B10: 2025-10-01 | C10: 0301049751 | D10: 73239990 | E10: AM-966 STEEL FRUIT BASKET (QTY 400 PCS/USD 1.017 PER PCS) AM-966 STEEL FRUIT BASKET (QTY 400 PCS/USD 1.017 PER PCS) | F10: =IFERROR(TRIM(LEFT(E10, FIND(" ", E10)-1)), "") -> AM-966 | G10: =IFERROR(TRIM(MID(E10, FIND(" ", E10)+1, FIND("(",E10)-FIND(" ",E10)-1)), "") -> STEEL FRUIT BASKET | H10: =IFERROR(MID(E10, FIND("(",E10)+1, FIND(")",E10)-FIND("(",E10)-1), "") -> QTY 400 PCS/USD 1.017 PER PCS | I10: =IFERROR(MID(E10, FIND("(",E10, FIND("P",E10)) + 1, FIND(" ",E10, FIND("(",E10)) - FIND("(",E10) - 1), "") -> QTY | J10: =IFERROR(--SUBSTITUTE(MID(E10, FIND("QTY", E10)+4, FIND(" ",E10, FIND("QTY",E10)+5)-FIND("QTY",E10)-4), ",",""),"") -> 400 | K10: =IFERROR( TRIM(_xlfn.TEXTAFTER(_xlfn.TEXTBEFORE(_xlfn.TEXTAFTER(tblRaw[[#This Row],[GOODS DESCRIPTION]],"QTY"),"/")," ")), tblRaw[[#This Row],[Unit of measure]] ) -> 400 PCS | L10: =IFERROR(--MID(E10, FIND("USD",E10)+4, FIND(" ",E10,FIND("USD",E10)+5)-FIND("USD",E10)-4), IFERROR(--MID(E10,FIND("CNY",E10)+4,FIND(" ",E10,FIND("CNY",E10)+5)-FIND("CNY",E10)-4),"")) -> 1.017 | M10: =IFERROR(IF(ISNUMBER(SEARCH("USD",E10)),"USD",IF(ISNUMBER(SEARCH("CNY",E10)),"CNY","")), "") -> USD | N10: 310 | O10: KGS | P10: 124.96932 | Q10: 38740.49 | R10: 1.4065202 | S10: 436.02127 | T10: 10886.1
A11: INNSA1 | B11: 2025-10-01 | C11: 0301049751 | D11: 73239990 | E11: AM-965 STEEL SPOON & FORK HOLDER (QTY 480 PCS/USD 0.734 PERPCS)AM-965 STEEL SPOON & FORK HOLDER (QTY 480 PCS/USD 0.734 PER | F11: =IFERROR(TRIM(LEFT(E11, FIND(" ", E11)-1)), "") -> AM-965 | G11: =IFERROR(TRIM(MID(E11, FIND(" ", E11)+1, FIND("(",E11)-FIND(" ",E11)-1)), "") -> STEEL SPOON & FORK HOLDER | H11: =IFERROR(MID(E11, FIND("(",E11)+1, FIND(")",E11)-FIND("(",E11)-1), "") -> QTY 480 PCS/USD 0.734 PERPCS | I11: =IFERROR(MID(E11, FIND("(",E11, FIND("P",E11)) + 1, FIND(" ",E11, FIND("(",E11)) - FIND("(",E11) - 1), "") -> QTY | J11: =IFERROR(--SUBSTITUTE(MID(E11, FIND("QTY", E11)+4, FIND(" ",E11, FIND("QTY",E11)+5)-FIND("QTY",E11)-4), ",",""),"") -> 480 | K11: =IFERROR( TRIM(_xlfn.TEXTAFTER(_xlfn.TEXTBEFORE(_xlfn.TEXTAFTER(tblRaw[[#This Row],[GOODS DESCRIPTION]],"QTY"),"/")," ")), tblRaw[[#This Row],[Unit of measure]] ) -> 480 PCS | L11: =IFERROR(--MID(E11, FIND("USD",E11)+4, FIND(" ",E11,FIND("USD",E11)+5)-FIND("USD",E11)-4), IFERROR(--MID(E11,FIND("CNY",E11)+4,FIND(" ",E11,FIND("CNY",E11)+5)-FIND("CNY",E11)-4),"")) -> 0.734 | M11: =IFERROR(IF(ISNUMBER(SEARCH("USD",E11)),"USD",IF(ISNUMBER(SEARCH("CNY",E11)),"CNY","")), "") -> USD | N11: 168 | O11: KGS | P11: 199.71571 | Q11: 33552.24 | R11: 2.2477852 | S11: 377.62791 | T11: 9428.1
A12: INNSA1 | B12: 2025-10-01 | C12: 0301049751 | D12: 73231000 | E12: 8001-2 STEEL SCRUBBER 2 PCS SET (QTY 336000 SETS/USD 0.139 PER SETS)8001-2 STEEL SCRUBBER 2 PCS SET (QTY 336000 SETS/USD 0.139 P | F12: =IFERROR(TRIM(LEFT(E12, FIND(" ", E12)-1)), "") -> 8001-2 | G12: =IFERROR(TRIM(MID(E12, FIND(" ", E12)+1, FIND("(",E12)-FIND(" ",E12)-1)), "") -> STEEL SCRUBBER 2 PCS SET | H12: =IFERROR(MID(E12, FIND("(",E12)+1, FIND(")",E12)-FIND("(",E12)-1), "") -> QTY 336000 SETS/USD 0.139 PER SETS | I12: =IFERROR(MID(E12, FIND("(",E12, FIND("P",E12)) + 1, FIND(" ",E12, FIND("(",E12)) - FIND("(",E12) - 1), "") -> QTY | J12: =IFERROR(--SUBSTITUTE(MID(E12, FIND("QTY", E12)+4, FIND(" ",E12, FIND("QTY",E12)+5)-FIND("QTY",E12)-4), ",",""),"") -> 336000 | K12: =IFERROR( TRIM(_xlfn.TEXTAFTER(_xlfn.TEXTBEFORE(_xlfn.TEXTAFTER(tblRaw[[#This Row],[GOODS DESCRIPTION]],"QTY"),"/")," ")), tblRaw[[#This Row],[Unit of measure]] ) -> 336000 SETS | L12: =IFERROR(--MID(E12, FIND("USD",E12)+4, FIND(" ",E12,FIND("USD",E12)+5)-FIND("USD",E12)-4), IFERROR(--MID(E12,FIND("CNY",E12)+4,FIND(" ",E12,FIND("CNY",E12)+5)-FIND("CNY",E12)-4),"")) -> 0.139 | M12: =IFERROR(IF(ISNUMBER(SEARCH("USD",E12)),"USD",IF(ISNUMBER(SEARCH("CNY",E12)),"CNY","")), "") -> USD | N12: 9800 | O12: KGS | P12: 456.12539 | Q12: 4470028.8 | R12: 5.1336566 | S12: 50309.835 | T12: 1965024.7
A13: INNSA1 | B13: 2025-09-27 | C13: 0301049751 | D13: 73231000 | E13: OKS-4156 STEEL SCRUBBER 6PCS SET (QTY: 93360 PCS /USD 0.228PER PCS)OKS-4156 STEEL SCRUBBER 6PCS SET (QTY: 93360 PCS /USD 0.228 | F13: =IFERROR(TRIM(LEFT(E13, FIND(" ", E13)-1)), "") -> OKS-4156 | G13: =IFERROR(TRIM(MID(E13, FIND(" ", E13)+1, FIND("(",E13)-FIND(" ",E13)-1)), "") -> STEEL SCRUBBER 6PCS SET | H13: =IFERROR(MID(E13, FIND("(",E13)+1, FIND(")",E13)-FIND("(",E13)-1), "") -> QTY: 93360 PCS /USD 0.228PER PCS | I13: =IFERROR(MID(E13, FIND("(",E13, FIND("P",E13)) + 1, FIND(" ",E13, FIND("(",E13)) - FIND("(",E13) - 1), "") -> QTY: | J13: =IFERROR(--SUBSTITUTE(MID(E13, FIND("QTY", E13)+4, FIND(" ",E13, FIND("QTY",E13)+5)-FIND("QTY",E13)-4), ",",""),"") -> 93360 | K13: =IFERROR( TRIM(_xlfn.TEXTAFTER(_xlfn.TEXTBEFORE(_xlfn.TEXTAFTER(tblRaw[[#This Row],[GOODS DESCRIPTION]],"QTY"),"/")," ")), tblRaw[[#This Row],[Unit of measure]] ) -> 93360 PCS | L13: =IFERROR(--MID(E13, FIND("USD",E13)+4, FIND(" ",E13,FIND("USD",E13)+5)-FIND("USD",E13)-4), IFERROR(--MID(E13,FIND("CNY",E13)+4,FIND(" ",E13,FIND("CNY",E13)+5)-FIND("CNY",E13)-4),"")) | M13: =IFERROR(IF(ISNUMBER(SEARCH("USD",E13)),"USD",IF(ISNUMBER(SEARCH("CNY",E13)),"CNY","")), "") -> USD | N13: 7496.03 | O13: KGS | P13: 263.57138 | Q13: 1975739 | R13: 2.9664758 | S13: 22236.792 | T13: 868534.9
A14: INNSA1 | B14: 2025-09-27 | C14: 0301049751 | D14: 73231000 | E14: 8001-2 STEEL SCRUBBER 2PCS SET (QTY: 168000 SETS/USD 0.139 PER SETS)8001-2 STEEL SCRUBBER 2PCS SET (QTY: 168000 SETS/USD 0.139 P | F14: =IFERROR(TRIM(LEFT(E14, FIND(" ", E14)-1)), "") -> 8001-2 | G14: =IFERROR(TRIM(MID(E14, FIND(" ", E14)+1, FIND("(",E14)-FIND(" ",E14)-1)), "") -> STEEL SCRUBBER 2PCS SET | H14: =IFERROR(MID(E14, FIND("(",E14)+1, FIND(")",E14)-FIND("(",E14)-1), "") -> QTY: 168000 SETS/USD 0.139 PER SETS | I14: =IFERROR(MID(E14, FIND("(",E14, FIND("P",E14)) + 1, FIND(" ",E14, FIND("(",E14)) - FIND("(",E14) - 1), "") -> QTY: | J14: =IFERROR(--SUBSTITUTE(MID(E14, FIND("QTY", E14)+4, FIND(" ",E14, FIND("QTY",E14)+5)-FIND("QTY",E14)-4), ",",""),"") -> 168000 | K14: =IFERROR( TRIM(_xlfn.TEXTAFTER(_xlfn.TEXTBEFORE(_xlfn.TEXTAFTER(tblRaw[[#This Row],[GOODS DESCRIPTION]],"QTY"),"/")," ")), tblRaw[[#This Row],[Unit of measure]] ) -> 168000 SETS | L14: =IFERROR(--MID(E14, FIND("USD",E14)+4, FIND(" ",E14,FIND("USD",E14)+5)-FIND("USD",E14)-4), IFERROR(--MID(E14,FIND("CNY",E14)+4,FIND(" ",E14,FIND("CNY",E14)+5)-FIND("CNY",E14)-4),"")) -> 0.139 | M14: =IFERROR(IF(ISNUMBER(SEARCH("USD",E14)),"USD",IF(ISNUMBER(SEARCH("CNY",E14)),"CNY","")), "") -> USD | N14: 4900 | O14: KGS | P14: 442.07294 | Q14: 2166157.4 | R14: 4.9754973 | S14: 24379.937 | T14: 952242.8
... A2080: INNSA1 | B2080: 2017-01-13 | C2080: 0301049751 | D2080: 73239990 | E2080: STAINLESS STEEL SPORTS BOTTLE 750ML S-308-C6-NP-20(TOTAL NET WT.284.83 KGS) | F2080: =IFERROR(TRIM(LEFT(E2080, FIND(" ", E2080)-1)), "") -> STAINLESS | G2080: =IFERROR(TRIM(MID(E2080, FIND(" ", E2080)+1, FIND("(",E2080)-FIND(" ",E2080)-1)), "") -> STEEL SPORTS BOTTLE 750ML S-308-C6-NP-20 | H2080: =IFERROR(MID(E2080, FIND("(",E2080)+1, FIND(")",E2080)-FIND("(",E2080)-1), "") -> TOTAL NET WT.284.83 KGS | I2080: =IFERROR(MID(E2080, FIND("(",E2080, FIND("P",E2080)) + 1, FIND(" ",E2080, FIND("(",E2080)) - FIND("(",E2080) - 1), "") -> TOTAL | J2080: =IFERROR(--SUBSTITUTE(MID(E2080, FIND("QTY", E2080)+4, FIND(" ",E2080, FIND("QTY",E2080)+5)-FIND("QTY",E2080)-4), ",",""),"") | K2080: =IFERROR( TRIM(_xlfn.TEXTAFTER(_xlfn.TEXTBEFORE(_xlfn.TEXTAFTER(tblRaw[[#This Row],[GOODS DESCRIPTION]],"QTY"),"/")," ")), tblRaw[[#This Row],[Unit of measure]] ) -> 0 | L2080: =IFERROR(--MID(E2080, FIND("USD",E2080)+4, FIND(" ",E2080,FIND("USD",E2080)+5)-FIND("USD",E2080)-4), IFERROR(--MID(E2080,FIND("CNY",E2080)+4,FIND(" ",E2080,FIND("CNY",E2080)+5)-FIND("CNY",E2080)-4),"")) | M2080: =IFERROR(IF(ISNUMBER(SEARCH("USD",E2080)),"USD",IF(ISNUMBER(SEARCH("CNY",E2080)),"CNY","")), "") | N2080: 1656 | O2080: PCS | P2080: 79.149233 | Q2080: 131071.13 | R2080: 1.1504249 | S2080: 1905.1036 | T2080: 22410.6

Sheet Cleaned Data
A1: PORT CODE | B1: DATE | C1: YEAR | D1: IEC | E1: HS CODE | F1: HS MAIN CATEGORY | G1: GOODS DESCRIPTION | H1: MODEL NAME | I1: MODEL NUMBER | J1: Capacity | K1: RAW QTY (from description) | L1: RAW UNIT (PCS / SET / etc) | M1: FINAL QUANTITY | N1: FINAL UNIT | O1: USD UNIT PRICE | P1: USD TOTAL VALUE | Q1: INR UNIT PRICE | R1: INR TOTAL VALUE | S1: DUTY PAID | T1: DUTY PER UNIT | U1: DUTY % | V1: CATEGORY (Steel / Other)
A2: INNSA1 | B2: 2025-10-28 | C2: =YEAR(B2) -> 2025 | D2: 0301049751 | E2: 73239990 | F2: =LEFT(E2,2) -> 73 | G2: TH5170 STEEL CUTLERY HOLDER (QTY:600 PCS/USD 2.03 PER PCS) TH5170 STEEL CUTLERY HOLDER (QTY:600 PCS/USD 2.03 PER PCS) | H2: =IFERROR(LEFT(G2, FIND(" ",G2)), "") -> TH5170 | I2: {=IFERROR(INDEX(_xlfn.TEXTSPLIT(E2," "),1), "")} -> 73239990 | J2: QTY:600 | K2: {=IF(ISERROR(SEARCH("QTY:", G2)), IF(ISERROR(SEARCH("TOTAL ", G2)), Raw [1]Data!N2, TRIM(MID(G2, SEARCH("TOTAL ", G2)+6, SEARCH(" ", G2&" ", SEARCH("TOTAL ", G2)+6) - SEARCH("TOTAL ", G2) - 6))), TRIM(MID(G2, SEARCH("QTY:", G2)+4, SEARCH(" ", G2, SEARCH("QTY:", G2)+4) - SEARCH("QTY:", G2) - 4)))} -> 600 | M2: =K2 -> 600 | N2: =L2 -> 0 | O2: {=IF(ISERROR(SEARCH("USD ", G2)), Raw [1]Data!S2, TRIM(MID(G2, SEARCH("USD ", G2)+4, SEARCH(" ", G2&" ", SEARCH("USD ", G2)+4) - SEARCH("USD ", G2) - 4)))} -> 2.03 | P2: =O2*M2 -> 1218 | Q2: {=Raw [1]Data!P2} -> #NAME? | R2: {=Raw [1]Data!Q2} -> #NAME? | S2: {=Raw [1]Data!T2} -> #NAME? | T2: =S2/M2 -> #NAME? | U2: =IF(R2<>0, (S2/R2)*100, 0) -> #NAME? | V2: =IF(OR(E2=73239990,E2=73231000,E2=73239390),"Steel","Other") -> Other
A3: INNSA1 | B3: 2025-10-28 | C3: =YEAR(B3) -> 2025 | D3: 0301049751 | E3: 73231000 | F3: =LEFT(E3,2) -> 73 | G3: 8001-2 STEEL SCRUBBER 2PCS SET (QTY: 336000 SETS/USD 0.139 PER SETS)8001-2 STEEL SCRUBBER 2PCS SET (QTY: 336000 SETS/USD 0.139 P | H3: =IFERROR(LEFT(G3, FIND(" ",G3)), "") -> 8001-2 | I3: {=IFERROR(INDEX(_xlfn.TEXTSPLIT(E3," "),1), "")} -> 73231000 | J3: QTY: | K3: {=IF(ISERROR(SEARCH("QTY:", G3)), IF(ISERROR(SEARCH("TOTAL ", G3)), Raw [1]Data!N3, TRIM(MID(G3, SEARCH("TOTAL ", G3)+6, SEARCH(" ", G3&" ", SEARCH("TOTAL ", G3)+6) - SEARCH("TOTAL ", G3) - 6))), TRIM(MID(G3, SEARCH("QTY:", G3)+4, SEARCH(" ", G3, SEARCH("QTY:", G3)+4) - SEARCH("QTY:", G3) - 4)))} | M3: =K3 | N3: =L3 -> 0 | O3: {=IF(ISERROR(SEARCH("USD ", G3)), Raw [1]Data!S3, TRIM(MID(G3, SEARCH("USD ", G3)+4, SEARCH(" ", G3&" ", SEARCH("USD ", G3)+4) - SEARCH("USD ", G3) - 4)))} -> 0.139 | P3: =O3*M3 -> #VALUE! | Q3: {=Raw [1]Data!P3} -> #NAME? | R3: {=Raw [1]Data!Q3} -> #NAME? | S3: {=Raw [1]Data!T3} -> #NAME? | T3: =S3/M3 -> #NAME? | U3: =IF(R3<>0, (S3/R3)*100, 0) -> #NAME? | V3: =IF(OR(E3=73239990,E3=73231000,E3=73239390),"Steel","Other") -> Other
A4: INNSA1 | B4: 2025-10-23 | C4: =YEAR(B4) -> 2025 | D4: 0301049751 | E4: 73239990 | F4: =LEFT(E4,2) -> 73 | G4: MILD STEEL MULTI FUNCTION CLOTH STAND (RYX-02-020) (QTY: 1,232 PCS/CNY:101 PER PCS)MILD STEEL MULTI FUNCTION CLOTH STAND (RYX-02-020) (QTY: 1,2 | H4: =IFERROR(LEFT(G4, FIND(" ",G4)), "") -> MILD | I4: {=IFERROR(INDEX(_xlfn.TEXTSPLIT(E4," "),1), "")} -> 73239990 | J4: RYX-02-020) | K4: {=IF(ISERROR(SEARCH("QTY:", G4)), IF(ISERROR(SEARCH("TOTAL ", G4)), Raw [1]Data!N4, TRIM(MID(G4, SEARCH("TOTAL ", G4)+6, SEARCH(" ", G4&" ", SEARCH("TOTAL ", G4)+6) - SEARCH("TOTAL ", G4) - 6))), TRIM(MID(G4, SEARCH("QTY:", G4)+4, SEARCH(" ", G4, SEARCH("QTY:", G4)+4) - SEARCH("QTY:", G4) - 4)))} | M4: =K4 | N4: =L4 -> 0 | O4: {=IF(ISERROR(SEARCH("USD ", G4)), Raw [1]Data!S4, TRIM(MID(G4, SEARCH("USD ", G4)+4, SEARCH(" ", G4&" ", SEARCH("USD ", G4)+4) - SEARCH("USD ", G4) - 4)))} -> #NAME? | P4: =O4*M4 -> #NAME? | Q4: {=Raw [1]Data!P4} -> #NAME? | R4: {=Raw [1]Data!Q4} -> #NAME? | S4: {=Raw [1]Data!T4} -> #NAME? | T4: =S4/M4 -> #NAME? | U4: =IF(R4<>0, (S4/R4)*100, 0) -> #NAME? | V4: =IF(OR(E4=73239990,E4=73231000,E4=73239390),"Steel","Other") -> Other
A5: INNSA1 | B5: 2025-10-13 | C5: =YEAR(B5) -> 2025 | D5: 0301049751 | E5: 73239990 | F5: =LEFT(E5,2) -> 73 | G5: SB-12 STEEL TEA STRAINER BIG (QTY 6336 PCS/USD 0.973 PER PCS)SB-12 STEEL TEA STRAINER BIG (QTY 6336 PCS/USD 0.973 PER PCS | H5: =IFERROR(LEFT(G5, FIND(" ",G5)), "") -> SB-12 | I5: {=IFERROR(INDEX(_xlfn.TEXTSPLIT(E5," "),1), "")} -> 73239990 | J5: QTY: | K5: {=IF(ISERROR(SEARCH("QTY:", G5)), IF(ISERROR(SEARCH("TOTAL ", G5)), Raw [1]Data!N5, TRIM(MID(G5, SEARCH("TOTAL ", G5)+6, SEARCH(" ", G5&" ", SEARCH("TOTAL ", G5)+6) - SEARCH("TOTAL ", G5) - 6))), TRIM(MID(G5, SEARCH("QTY:", G5)+4, SEARCH(" ", G5, SEARCH("QTY:", G5)+4) - SEARCH("QTY:", G5) - 4)))} -> #NAME? | M5: =K5 -> #NAME? | N5: =L5 -> 0 | O5: {=IF(ISERROR(SEARCH("USD ", G5)), Raw [1]Data!S5, TRIM(MID(G5, SEARCH("USD ", G5)+4, SEARCH(" ", G5&" ", SEARCH("USD ", G5)+4) - SEARCH("USD ", G5) - 4)))} -> 0.973 | P5: =O5*M5 -> #NAME? | Q5: {=Raw [1]Data!P5} -> #NAME? | R5: {=Raw [1]Data!Q5} -> #NAME? | S5: {=Raw [1]Data!T5} -> #NAME? | T5: =S5/M5 -> #NAME? | U5: =IF(R5<>0, (S5/R5)*100, 0) -> #NAME? | V5: =IF(OR(E5=73239990,E5=73231000,E5=73239390),"Steel","Other") -> Other
A6: INNSA1 | B6: 2025-10-13 | C6: =YEAR(B6) -> 2025 | D6: 0301049751 | E6: 73239990 | F6: =LEFT(E6,2) -> 73 | G6: SB-12 STEEL TEA STRAINER BIG (QTY 43038 PCS/USD 0.9718 PER PCS)SB-12 STEEL TEA STRAINER BIG (QTY 43038 PCS/USD 0.9718 PER P | H6: =IFERROR(LEFT(G6, FIND(" ",G6)), "") -> SB-12 | I6: {=IFERROR(INDEX(_xlfn.TEXTSPLIT(E6," "),1), "")} -> 73239990 | J6: QTY | K6: {=IF(ISERROR(SEARCH("QTY:", G6)), IF(ISERROR(SEARCH("TOTAL ", G6)), Raw [1]Data!N6, TRIM(MID(G6, SEARCH("TOTAL ", G6)+6, SEARCH(" ", G6&" ", SEARCH("TOTAL ", G6)+6) - SEARCH("TOTAL ", G6) - 6))), TRIM(MID(G6, SEARCH("QTY:", G6)+4, SEARCH(" ", G6, SEARCH("QTY:", G6)+4) - SEARCH("QTY:", G6) - 4)))} -> #NAME? | M6: =K6 -> #NAME? | N6: =L6 -> 0 | O6: {=IF(ISERROR(SEARCH("USD ", G6)), Raw [1]Data!S6, TRIM(MID(G6, SEARCH("USD ", G6)+4, SEARCH(" ", G6&" ", SEARCH("USD ", G6)+4) - SEARCH("USD ", G6) - 4)))} -> 0.9718 | P6: =O6*M6 -> #NAME? | Q6: {=Raw [1]Data!P6} -> #NAME? | R6: {=Raw [1]Data!Q6} -> #NAME? | S6: {=Raw [1]Data!T6} -> #NAME? | T6: =S6/M6 -> #NAME? | U6: =IF(R6<>0, (S6/R6)*100, 0) -> #NAME? | V6: =IF(OR(E6=73239990,E6=73231000,E6=73239390),"Steel","Other") -> Other
A7: INNSA1 | B7: 2025-10-08 | C7: =YEAR(B7) -> 2025 | D7: 0301049751 | E7: 73239990 | F7: =LEFT(E7,2) -> 73 | G7: STEEL HANGER WITH HOOK (SL-89) (QTY:70056 PCS/CNY:7.45 PER PCS)STEEL HANGER WITH HOOK (SL-89) (QTY:70056 PCS/:7.45 | H7: =IFERROR(LEFT(G7, FIND(" ",G7)), "") -> STEEL | I7: {=IFERROR(INDEX(_xlfn.TEXTSPLIT(E7," "),1), "")} -> 73239990 | J7: SL-89) | K7: {=IF(ISERROR(SEARCH("QTY:", G7)), IF(ISERROR(SEARCH("TOTAL ", G7)), Raw [1]Data!N7, TRIM(MID(G7, SEARCH("TOTAL ", G7)+6, SEARCH(" ", G7&" ", SEARCH("TOTAL ", G7)+6) - SEARCH("TOTAL ", G7) - 6))), TRIM(MID(G7, SEARCH("QTY:", G7)+4, SEARCH(" ", G7, SEARCH("QTY:", G7)+4) - SEARCH("QTY:", G7) - 4)))} -> 70056 | M7: =K7 -> 70056 | N7: =L7 -> 0 | O7: {=IF(ISERROR(SEARCH("USD ", G7)), Raw [1]Data!S7, TRIM(MID(G7, SEARCH("USD ", G7)+4, SEARCH(" ", G7&" ", SEARCH("USD ", G7)+4) - SEARCH("USD ", G7) - 4)))} -> #NAME? | P7: =O7*M7 -> #NAME? | Q7: {=Raw [1]Data!P7} -> #NAME? | R7: {=Raw [1]Data!Q7} -> #NAME? | S7: {=Raw [1]Data!T7} -> #NAME? | T7: =S7/M7 -> #NAME? | U7: =IF(R7<>0, (S7/R7)*100, 0) -> #NAME? | V7: =IF(OR(E7=73239990,E7=73231000,E7=73239390),"Steel","Other") -> Other
A8: INNSA1 | B8: 2025-10-06 | C8: =YEAR(B8) -> 2025 | D8: 0301049751 | E8: 73239990 | F8: =LEFT(E8,2) -> 73 | G8: STEEL HANGER 10PCS SET (AM-969) (QTY: 480 SET/USD 0.819 PERSET)STEEL HANGER 10PCS SET (AM-969) (QTY: 480 SET/USD 0.819 PER | H8: =IFERROR(LEFT(G8, FIND(" ",G8)), "") -> STEEL | I8: {=IFERROR(INDEX(_xlfn.TEXTSPLIT(E8," "),1), "")} -> 73239990 | J8: AM-969) | K8: {=IF(ISERROR(SEARCH("QTY:", G8)), IF(ISERROR(SEARCH("TOTAL ", G8)), Raw [1]Data!N8, TRIM(MID(G8, SEARCH("TOTAL ", G8)+6, SEARCH(" ", G8&" ", SEARCH("TOTAL ", G8)+6) - SEARCH("TOTAL ", G8) - 6))), TRIM(MID(G8, SEARCH("QTY:", G8)+4, SEARCH(" ", G8, SEARCH("QTY:", G8)+4) - SEARCH("QTY:", G8) - 4)))} | M8: =K8 | N8: =L8 -> 0 | O8: {=IF(ISERROR(SEARCH("USD ", G8)), Raw [1]Data!S8, TRIM(MID(G8, SEARCH("USD ", G8)+4, SEARCH(" ", G8&" ", SEARCH("USD ", G8)+4) - SEARCH("USD ", G8) - 4)))} -> 0.819 | P8: =O8*M8 -> #VALUE! | Q8: {=Raw [1]Data!P8} -> #NAME? | R8: {=Raw [1]Data!Q8} -> #NAME? | S8: {=Raw [1]Data!T8} -> #NAME? | T8: =S8/M8 -> #NAME? | U8: =IF(R8<>0, (S8/R8)*100, 0) -> #NAME? | V8: =IF(OR(E8=73239990,E8=73231000,E8=73239390),"Steel","Other") -> Other
A9: INNSA1 | B9: 2025-10-01 | C9: =YEAR(B9) -> 2025 | D9: 0301049751 | E9: 73239990 | F9: =LEFT(E9,2) -> 73 | G9: AM-967 STEEL FRUIT BASKET (QTY 400 PCS/USD 1.031 PER PCS) AM-967 STEEL FRUIT BASKET (QTY 400 PCS/USD 1.031 PER PCS) | H9: =IFERROR(LEFT(G9, FIND(" ",G9)), "") -> AM-967 | I9: {=IFERROR(INDEX(_xlfn.TEXTSPLIT(E9," "),1), "")} -> 73239990 | J9: QTY | K9: {=IF(ISERROR(SEARCH("QTY:", G9)), IF(ISERROR(SEARCH("TOTAL ", G9)), Raw [1]Data!N9, TRIM(MID(G9, SEARCH("TOTAL ", G9)+6, SEARCH(" ", G9&" ", SEARCH("TOTAL ", G9)+6) - SEARCH("TOTAL ", G9) - 6))), TRIM(MID(G9, SEARCH("QTY:", G9)+4, SEARCH(" ", G9, SEARCH("QTY:", G9)+4) - SEARCH("QTY:", G9) - 4)))} -> #NAME? | M9: =K9 -> #NAME? | N9: =L9 -> 0 | O9: {=IF(ISERROR(SEARCH("USD ", G9)), Raw [1]Data!S9, TRIM(MID(G9, SEARCH("USD ", G9)+4, SEARCH(" ", G9&" ", SEARCH("USD ", G9)+4) - SEARCH("USD ", G9) - 4)))} -> 1.031 | P9: =O9*M9 -> #NAME? | Q9: {=Raw [1]Data!P9} -> #NAME? | R9: {=Raw [1]Data!Q9} -> #NAME? | S9: {=Raw [1]Data!T9} -> #NAME? | T9: =S9/M9 -> #NAME? | U9: =IF(R9<>0, (S9/R9)*100, 0) -> #NAME? | V9: =IF(OR(E9=73239990,E9=73231000,E9=73239390),"Steel","Other") -> Other
A10: INNSA1 | B10: 2025-10-01 | C10: =YEAR(B10) -> 2025 | D10: 0301049751 | E10: 73239990 | F10: =LEFT(E10,2) -> 73 | G10: AM-966 STEEL FRUIT BASKET (QTY 400 PCS/USD 1.017 PER PCS) AM-966 STEEL FRUIT BASKET (QTY 400 PCS/USD 1.017 PER PCS) | H10: =IFERROR(LEFT(G10, FIND(" ",G10)), "") -> AM-966 | I10: {=IFERROR(INDEX(_xlfn.TEXTSPLIT(E10," "),1), "")} -> 73239990 | J10: QTY | K10: {=IF(ISERROR(SEARCH("QTY:", G10)), IF(ISERROR(SEARCH("TOTAL ", G10)), Raw [1]Data!N10, TRIM(MID(G10, SEARCH("TOTAL ", G10)+6, SEARCH(" ", G10&" ", SEARCH("TOTAL ", G10)+6) - SEARCH("TOTAL ", G10) - 6))), TRIM(MID(G10, SEARCH("QTY:", G10)+4, SEARCH(" ", G10, SEARCH("QTY:", G10)+4) - SEARCH("QTY:", G10) - 4)))} -> #NAME? | M10: =K10 -> #NAME? | N10: =L10 -> 0 | O10: {=IF(ISERROR(SEARCH("USD ", G10)), Raw [1]Data!S10, TRIM(MID(G10, SEARCH("USD ", G10)+4, SEARCH(" ", G10&" ", SEARCH("USD ", G10)+4) - SEARCH("USD ", G10) - 4)))} -> 1.017 | P10: =O10*M10 -> #NAME? | Q10: {=Raw [1]Data!P10} -> #NAME? | R10: {=Raw [1]Data!Q10} -> #NAME? | S10: {=Raw [1]Data!T10} -> #NAME? | T10: =S10/M10 -> #NAME? | U10: =IF(R10<>0, (S10/R10)*100, 0) -> #NAME? | V10: =IF(OR(E10=73239990,E10=73231000,E10=73239390),"Steel","Other") -> Other
A11: INNSA1 | B11: 2025-10-01 | C11: =YEAR(B11) -> 2025 | D11: 0301049751 | E11: 73239990 | F11: =LEFT(E11,2) -> 73 | G11: AM-965 STEEL SPOON & FORK HOLDER (QTY 480 PCS/USD 0.734 PERPCS)AM-965 STEEL SPOON & FORK HOLDER (QTY 480 PCS/USD 0.734 PER | H11: =IFERROR(LEFT(G11, FIND(" ",G11)), "") -> AM-965 | I11: {=IFERROR(INDEX(_xlfn.TEXTSPLIT(E11," "),1), "")} -> 73239990 | J11: QTY | K11: {=IF(ISERROR(SEARCH("QTY:", G11)), IF(ISERROR(SEARCH("TOTAL ", G11)), Raw [1]Data!N11, TRIM(MID(G11, SEARCH("TOTAL ", G11)+6, SEARCH(" ", G11&" ", SEARCH("TOTAL ", G11)+6) - SEARCH("TOTAL ", G11) - 6))), TRIM(MID(G11, SEARCH("QTY:", G11)+4, SEARCH(" ", G11, SEARCH("QTY:", G11)+4) - SEARCH("QTY:", G11) - 4)))} -> #NAME? | M11: =K11 -> #NAME? | N11: =L11 -> 0 | O11: {=IF(ISERROR(SEARCH("USD ", G11)), Raw [1]Data!S11, TRIM(MID(G11, SEARCH("USD ", G11)+4, SEARCH(" ", G11&" ", SEARCH("USD ", G11)+4) - SEARCH("USD ", G11) - 4)))} -> 0.734 | P11: =O11*M11 -> #NAME? | Q11: {=Raw [1]Data!P11} -> #NAME? | R11: {=Raw [1]Data!Q11} -> #NAME? | S11: {=Raw [1]Data!T11} -> #NAME? | T11: =S11/M11 -> #NAME? | U11: =IF(R11<>0, (S11/R11)*100, 0) -> #NAME? | V11: =IF(OR(E11=73239990,E11=73231000,E11=73239390),"Steel","Other") -> Other
A12: INNSA1 | B12: 2025-10-01 | C12: =YEAR(B12) -> 2025 | D12: 0301049751 | E12: 73231000 | F12: =LEFT(E12,2) -> 73 | G12: 8001-2 STEEL SCRUBBER 2 PCS SET (QTY 336000 SETS/USD 0.139 PER SETS)8001-2 STEEL SCRUBBER 2 PCS SET (QTY 336000 SETS/USD 0.139 P | H12: =IFERROR(LEFT(G12, FIND(" ",G12)), "") -> 8001-2 | I12: {=IFERROR(INDEX(_xlfn.TEXTSPLIT(E12," "),1), "")} -> 73231000 | J12: QTY | K12: {=IF(ISERROR(SEARCH("QTY:", G12)), IF(ISERROR(SEARCH("TOTAL ", G12)), Raw [1]Data!N12, TRIM(MID(G12, SEARCH("TOTAL ", G12)+6, SEARCH(" ", G12&" ", SEARCH("TOTAL ", G12)+6) - SEARCH("TOTAL ", G12) - 6))), TRIM(MID(G12, SEARCH("QTY:", G12)+4, SEARCH(" ", G12, SEARCH("QTY:", G12)+4) - SEARCH("QTY:", G12) - 4)))} -> #NAME? | M12: =K12 -> #NAME? | N12: =L12 -> 0 | O12: {=IF(ISERROR(SEARCH("USD ", G12)), Raw [1]Data!S12, TRIM(MID(G12, SEARCH("USD ", G12)+4, SEARCH(" ", G12&" ", SEARCH("USD ", G12)+4) - SEARCH("USD ", G12) - 4)))} -> 0.139 | P12: =O12*M12 -> #NAME? | Q12: {=Raw [1]Data!P12} -> #NAME? | R12: {=Raw [1]Data!Q12} -> #NAME? | S12: {=Raw [1]Data!T12} -> #NAME? | T12: =S12/M12 -> #NAME? | U12: =IF(R12<>0, (S12/R12)*100, 0) -> #NAME? | V12: =IF(OR(E12=73239990,E12=73231000,E12=73239390),"Steel","Other") -> Other
A13: INNSA1 | B13: 2025-09-27 | C13: =YEAR(B13) -> 2025 | D13: 0301049751 | E13: 73231000 | F13: =LEFT(E13,2) -> 73 | G13: OKS-4156 STEEL SCRUBBER 6PCS SET (QTY: 93360 PCS /USD 0.228PER PCS)OKS-4156 STEEL SCRUBBER 6PCS SET (QTY: 93360 PCS /USD 0.228 | H13: =IFERROR(LEFT(G13, FIND(" ",G13)), "") -> OKS-4156 | I13: {=IFERROR(INDEX(_xlfn.TEXTSPLIT(E13," "),1), "")} -> 73231000 | J13: QTY: | K13: {=IF(ISERROR(SEARCH("QTY:", G13)), IF(ISERROR(SEARCH("TOTAL ", G13)), Raw [1]Data!N13, TRIM(MID(G13, SEARCH("TOTAL ", G13)+6, SEARCH(" ", G13&" ", SEARCH("TOTAL ", G13)+6) - SEARCH("TOTAL ", G13) - 6))), TRIM(MID(G13, SEARCH("QTY:", G13)+4, SEARCH(" ", G13, SEARCH("QTY:", G13)+4) - SEARCH("QTY:", G13) - 4)))} | M13: =K13 | N13: =L13 -> 0 | O13: {=IF(ISERROR(SEARCH("USD ", G13)), Raw [1]Data!S13, TRIM(MID(G13, SEARCH("USD ", G13)+4, SEARCH(" ", G13&" ", SEARCH("USD ", G13)+4) - SEARCH("USD ", G13) - 4)))} -> 0.228PER | P13: =O13*M13 -> #VALUE! | Q13: {=Raw [1]Data!P13} -> #NAME? | R13: {=Raw [1]Data!Q13} -> #NAME? | S13: {=Raw [1]Data!T13} -> #NAME? | T13: =S13/M13 -> #NAME? | U13: =IF(R13<>0, (S13/R13)*100, 0) -> #NAME? | V13: =IF(OR(E13=73239990,E13=73231000,E13=73239390),"Steel","Other") -> Other
... A155: INNSA1 | B155: 2024-12-20 | C155: =YEAR(B155) -> 2024 | D155: 0301049751 | E155: 73239990 | F155: =LEFT(E155,2) -> 73 | G155: STEEL SALT BOTTLE (NP-19) (QTY: 7200 PC/USD 0.441 PER PC) STEEL SALT BOTTLE (NP-19) (QTY: 7200 PC/USD 0.441 PER PC) | H155: =IFERROR(LEFT(G155, FIND(" ",G155)), "") -> STEEL | I155: {=IFERROR(INDEX(_xlfn.TEXTSPLIT(E155," "),1), "")} -> 73239990 | J155: QTY: 7 | K155: {=IF(ISERROR(SEARCH("QTY:", G155)), IF(ISERROR(SEARCH("TOTAL ", G155)), Raw [1]Data!N155, TRIM(MID(G155, SEARCH("TOTAL ", G155)+6, SEARCH(" ", G155&" ", SEARCH("TOTAL ", G155)+6) - SEARCH("TOTAL ", G155) - 6))), TRIM(MID(G155, SEARCH("QTY:", G155)+4, SEARCH(" ", G155, SEARCH("QTY:", G155)+4) - SEARCH("QTY:", G155) - 4)))} | M155: =K155 | N155: =L155 -> 0 | O155: {=IF(ISERROR(SEARCH("USD ", G155)), Raw [1]Data!S155, TRIM(MID(G155, SEARCH("USD ", G155)+4, SEARCH(" ", G155&" ", SEARCH("USD ", G155)+4) - SEARCH("USD ", G155) - 4)))} -> 0.441 | P155: =O155*M155 -> #VALUE! | Q155: {=Raw [1]Data!P155} -> #NAME? | R155: {=Raw [1]Data!Q155} -> #NAME? | S155: {=Raw [1]Data!T155} -> #NAME? | T155: =S155/M155 -> #NAME? | U155: =IF(R155<>0, (S155/R155)*100, 0) -> #NAME? | V155: =IF(OR(E155=73239990,E155=73231000,E155=73239390),"Steel","Other") -> Other
A156: INNSA1 | B156: 2024-12-04 | C156: =YEAR(B156) -> 2024 | D156: 0301049751 | E156: 73239990 | F156: =LEFT(E156,2) -> 73 | G156: RYX-02-020 MILD STEEL MULTI FUNCTION CLOTH STAND (QTY :1232NUM/CNY 101.00 PER NUM) | H156: =IFERROR(LEFT(G156, FIND(" ",G156)), "") -> RYX-02-020 | I156: {=IFERROR(INDEX(_xlfn.TEXTSPLIT(E156," "),1), "")} -> 73239990 | K156: {=IF(ISERROR(SEARCH("QTY:", G156)), IF(ISERROR(SEARCH("TOTAL ", G156)), Raw [1]Data!N156, TRIM(MID(G156, SEARCH("TOTAL ", G156)+6, SEARCH(" ", G156&" ", SEARCH("TOTAL ", G156)+6) - SEARCH("TOTAL ", G156) - 6))), TRIM(MID(G156, SEARCH("QTY:", G156)+4, SEARCH(" ", G156, SEARCH("QTY:", G156)+4) - SEARCH("QTY:", G156) - 4)))} -> #NAME? | M156: =K156 -> #NAME? | N156: =L156 -> 0 | O156: {=IF(ISERROR(SEARCH("USD ", G156)), Raw [1]Data!S156, TRIM(MID(G156, SEARCH("USD ", G156)+4, SEARCH(" ", G156&" ", SEARCH("USD ", G156)+4) - SEARCH("USD ", G156) - 4)))} -> #NAME? | P156: =O156*M156 -> #NAME? | Q156: {=Raw [1]Data!P156} -> #NAME? | R156: {=Raw [1]Data!Q156} -> #NAME? | S156: {=Raw [1]Data!T156} -> #NAME? | T156: =S156/M156 -> #NAME? | U156: =IF(R156<>0, (S156/R156)*100, 0) -> #NAME? | V156: =IF(OR(E156=73239990,E156=73231000,E156=73239390),"Steel","Other") -> Other
A157: INNSA1 | B157: 2024-11-30 | C157: =YEAR(B157) -> 2024 | D157: 0301049751 | E157: 73239990 | F157: =LEFT(E157,2) -> 73 | G157: RYX-02-020 MILD STEEL MULTI FUNCTION CLOTH STAND (QTY :1232NUM/CNY 101.00 PER NUM) | H157: =IFERROR(LEFT(G157, FIND(" ",G157)), "") -> RYX-02-020 | I157: {=IFERROR(INDEX(_xlfn.TEXTSPLIT(E157," "),1), "")} -> 73239990 | K157: {=IF(ISERROR(SEARCH("QTY:", G157)), IF(ISERROR(SEARCH("TOTAL ", G157)), Raw [1]Data!N157, TRIM(MID(G157, SEARCH("TOTAL ", G157)+6, SEARCH(" ", G157&" ", SEARCH("TOTAL ", G157)+6) - SEARCH("TOTAL ", G157) - 6))), TRIM(MID(G157, SEARCH("QTY:", G157)+4, SEARCH(" ", G157, SEARCH("QTY:", G157)+4) - SEARCH("QTY:", G157) - 4)))} -> #NAME? | M157: =K157 -> #NAME? | N157: =L157 -> 0 | O157: {=IF(ISERROR(SEARCH("USD ", G157)), Raw [1]Data!S157, TRIM(MID(G157, SEARCH("USD ", G157)+4, SEARCH(" ", G157&" ", SEARCH("USD ", G157)+4) - SEARCH("USD ", G157) - 4)))} -> #NAME? | P157: =O157*M157 -> #NAME? | Q157: {=Raw [1]Data!P157} -> #NAME? | R157: {=Raw [1]Data!Q157} -> #NAME? | S157: {=Raw [1]Data!T157} -> #NAME? | T157: =S157/M157 -> #NAME? | U157: =IF(R157<>0, (S157/R157)*100, 0) -> #NAME? | V157: =IF(OR(E157=73239990,E157=73231000,E157=73239390),"Steel","Other") -> Other
A158: INNSA1 | B158: 2024-11-27 | C158: =YEAR(B158) -> 2024 | D158: 0301049751 | E158: 73239990 | F158: =LEFT(E158,2) -> 73 | G158: GS-47 STEEL GIFT BOX HEART SHAPE (QTY:44280 PCS/USD 0.212 PER PCS) | H158: =IFERROR(LEFT(G158, FIND(" ",G158)), "") -> GS-47 | I158: {=IFERROR(INDEX(_xlfn.TEXTSPLIT(E158," "),1), "")} -> 73239990 | J158: QTY:44280 | K158: {=IF(ISERROR(SEARCH("QTY:", G158)), IF(ISERROR(SEARCH("TOTAL ", G158)), Raw [1]Data!N158, TRIM(MID(G158, SEARCH("TOTAL ", G158)+6, SEARCH(" ", G158&" ", SEARCH("TOTAL ", G158)+6) - SEARCH("TOTAL ", G158) - 6))), TRIM(MID(G158, SEARCH("QTY:", G158)+4, SEARCH(" ", G158, SEARCH("QTY:", G158)+4) - SEARCH("QTY:", G158) - 4)))} -> 44280 | M158: =K158 -> 44280 | N158: =L158 -> 0 | O158: {=IF(ISERROR(SEARCH("USD ", G158)), Raw [1]Data!S158, TRIM(MID(G158, SEARCH("USD ", G158)+4, SEARCH(" ", G158&" ", SEARCH("USD ", G158)+4) - SEARCH("USD ", G158) - 4)))} -> 0.212 | P158: =O158*M158 -> 9387.36 | Q158: {=Raw [1]Data!P158} -> #NAME? | R158: {=Raw [1]Data!Q158} -> #NAME? | S158: {=Raw [1]Data!T158} -> #NAME? | T158: =S158/M158 -> #NAME? | U158: =IF(R158<>0, (S158/R158)*100, 0) -> #NAME? | V158: =IF(OR(E158=73239990,E158=73231000,E158=73239390),"Steel","Other") -> Other
A159: INNSA1 | B159: 2024-11-27 | C159: =YEAR(B159) -> 2024 | D159: 0301049751 | E159: 73239990 | F159: =LEFT(E159,2) -> 73 | G159: GS-47 STEEL GIFT BOX HEART SHAPE (QTY:6120 PCS/UDS 0.211 PERPCS) | H159: =IFERROR(LEFT(G159, FIND(" ",G159)), "") -> GS-47 | I159: {=IFERROR(INDEX(_xlfn.TEXTSPLIT(E159," "),1), "")} -> 73239990 | J159: QTY:6120 | K159: {=IF(ISERROR(SEARCH("QTY:", G159)), IF(ISERROR(SEARCH("TOTAL ", G159)), Raw [1]Data!N159, TRIM(MID(G159, SEARCH("TOTAL ", G159)+6, SEARCH(" ", G159&" ", SEARCH("TOTAL ", G159)+6) - SEARCH("TOTAL ", G159) - 6))), TRIM(MID(G159, SEARCH("QTY:", G159)+4, SEARCH(" ", G159, SEARCH("QTY:", G159)+4) - SEARCH("QTY:", G159) - 4)))} -> 6120 | M159: =K159 -> 6120 | N159: =L159 -> 0 | O159: {=IF(ISERROR(SEARCH("USD ", G159)), Raw [1]Data!S159, TRIM(MID(G159, SEARCH("USD ", G159)+4, SEARCH(" ", G159&" ", SEARCH("USD ", G159)+4) - SEARCH("USD ", G159) - 4)))} -> #NAME? | P159: =O159*M159 -> #NAME? | Q159: {=Raw [1]Data!P159} -> #NAME? | R159: {=Raw [1]Data!Q159} -> #NAME? | S159: {=Raw [1]Data!T159} -> #NAME? | T159: =S159/M159 -> #NAME? | U159: =IF(R159<>0, (S159/R159)*100, 0) -> #NAME? | V159: =IF(OR(E159=73239990,E159=73231000,E159=73239390),"Steel","Other") -> Other
A160: INNSA1 | B160: 2024-11-19 | C160: =YEAR(B160) -> 2024 | D160: 0301049751 | E160: 73231000 | F160: =LEFT(E160,2) -> 73 | G160: SS SCRUBBER 3PCS SET (SS410) (QTY: 119160 SET/USD 0.16 PER SET) | H160: =IFERROR(LEFT(G160, FIND(" ",G160)), "") -> SS | I160: {=IFERROR(INDEX(_xlfn.TEXTSPLIT(E160," "),1), "")} -> 73231000 | J160: SS410) | K160: {=IF(ISERROR(SEARCH("QTY:", G160)), IF(ISERROR(SEARCH("TOTAL ", G160)), Raw [1]Data!N160, TRIM(MID(G160, SEARCH("TOTAL ", G160)+6, SEARCH(" ", G160&" ", SEARCH("TOTAL ", G160)+6) - SEARCH("TOTAL ", G160) - 6))), TRIM(MID(G160, SEARCH("QTY:", G160)+4, SEARCH(" ", G160, SEARCH("QTY:", G160)+4) - SEARCH("QTY:", G160) - 4)))} | M160: =K160 | N160: =L160 -> 0 | O160: {=IF(ISERROR(SEARCH("USD ", G160)), Raw [1]Data!S160, TRIM(MID(G160, SEARCH("USD ", G160)+4, SEARCH(" ", G160&" ", SEARCH("USD ", G160)+4) - SEARCH("USD ", G160) - 4)))} -> 0.16 | P160: =O160*M160 -> #VALUE! | Q160: {=Raw [1]Data!P160} -> #NAME? | R160: {=Raw [1]Data!Q160} -> #NAME? | S160: {=Raw [1]Data!T160} -> #NAME? | T160: =S160/M160 -> #NAME? | U160: =IF(R160<>0, (S160/R160)*100, 0) -> #NAME? | V160: =IF(OR(E160=73239990,E160=73231000,E160=73239390),"Steel","Other") -> Other
A161: INNSA1 | B161: 2024-11-12 | C161: =YEAR(B161) -> 2024 | D161: 0301049751 | E161: 73231000 | F161: =LEFT(E161,2) -> 73 | G161: STEEL SCRUBBER (8001-12) (QTY: 278640 NOS/USD 0.084 PER NOS) | H161: =IFERROR(LEFT(G161, FIND(" ",G161)), "") -> STEEL | I161: {=IFERROR(INDEX(_xlfn.TEXTSPLIT(E161," "),1), "")} -> 73231000 | K161: {=IF(ISERROR(SEARCH("QTY:", G161)), IF(ISERROR(SEARCH("TOTAL ", G161)), Raw [1]Data!N161, TRIM(MID(G161, SEARCH("TOTAL ", G161)+6, SEARCH(" ", G161&" ", SEARCH("TOTAL ", G161)+6) - SEARCH("TOTAL ", G161) - 6))), TRIM(MID(G161, SEARCH("QTY:", G161)+4, SEARCH(" ", G161, SEARCH("QTY:", G161)+4) - SEARCH("QTY:", G161) - 4)))} | M161: =K161 | N161: =L161 -> 0 | O161: {=IF(ISERROR(SEARCH("USD ", G161)), Raw [1]Data!S161, TRIM(MID(G161, SEARCH("USD ", G161)+4, SEARCH(" ", G161&" ", SEARCH("USD ", G161)+4) - SEARCH("USD ", G161) - 4)))} -> 0.084 | P161: =O161*M161 -> #VALUE! | Q161: {=Raw [1]Data!P161} -> #NAME? | R161: {=Raw [1]Data!Q161} -> #NAME? | S161: {=Raw [1]Data!T161} -> #NAME? | T161: =S161/M161 -> #NAME? | U161: =IF(R161<>0, (S161/R161)*100, 0) -> #NAME? | V161: =IF(OR(E161=73239990,E161=73231000,E161=73239390),"Steel","Other") -> Other
A162: INNSA1 | B162: 2024-11-12 | C162: =YEAR(B162) -> 2024 | D162: 0301049751 | E162: 73231000 | F162: =LEFT(E162,2) -> 73 | G162: STEEL SCRUBBER 2 PCS SET (8001-2) (QTY:168000 SETS/USD:0.148PER SET) | H162: =IFERROR(LEFT(G162, FIND(" ",G162)), "") -> STEEL | I162: {=IFERROR(INDEX(_xlfn.TEXTSPLIT(E162," "),1), "")} -> 73231000 | J162: 8001-2) | K162: {=IF(ISERROR(SEARCH("QTY:", G162)), IF(ISERROR(SEARCH("TOTAL ", G162)), Raw [1]Data!N162, TRIM(MID(G162, SEARCH("TOTAL ", G162)+6, SEARCH(" ", G162&" ", SEARCH("TOTAL ", G162)+6) - SEARCH("TOTAL ", G162) - 6))), TRIM(MID(G162, SEARCH("QTY:", G162)+4, SEARCH(" ", G162, SEARCH("QTY:", G162)+4) - SEARCH("QTY:", G162) - 4)))} -> 168000 | M162: =K162 -> 168000 | N162: =L162 -> 0 | O162: {=IF(ISERROR(SEARCH("USD ", G162)), Raw [1]Data!S162, TRIM(MID(G162, SEARCH("USD ", G162)+4, SEARCH(" ", G162&" ", SEARCH("USD ", G162)+4) - SEARCH("USD ", G162) - 4)))} -> #NAME? | P162: =O162*M162 -> #NAME? | Q162: {=Raw [1]Data!P162} -> #NAME? | R162: {=Raw [1]Data!Q162} -> #NAME? | S162: {=Raw [1]Data!T162} -> #NAME? | T162: =S162/M162 -> #NAME? | U162: =IF(R162<>0, (S162/R162)*100, 0) -> #NAME? | V162: =IF(OR(E162=73239990,E162=73231000,E162=73239390),"Steel","Other") -> Other
A163: INNSA1 | B163: 2024-11-05 | C163: =YEAR(B163) -> 2024 | D163: 0301049751 | E163: 73239990 | F163: =LEFT(E163,2) -> 73 | G163: HOUSEHOLD STEEL HOOK 3PCS SET (3888) (QTY: 181872 PCS / USD0.260 PER PCS) | H163: =IFERROR(LEFT(G163, FIND(" ",G163)), "") -> HOUSEHOLD | I163: {=IFERROR(INDEX(_xlfn.TEXTSPLIT(E163," "),1), "")} -> 73239990 | J163: 3888) | K163: {=IF(ISERROR(SEARCH("QTY:", G163)), IF(ISERROR(SEARCH("TOTAL ", G163)), Raw [1]Data!N163, TRIM(MID(G163, SEARCH("TOTAL ", G163)+6, SEARCH(" ", G163&" ", SEARCH("TOTAL ", G163)+6) - SEARCH("TOTAL ", G163) - 6))), TRIM(MID(G163, SEARCH("QTY:", G163)+4, SEARCH(" ", G163, SEARCH("QTY:", G163)+4) - SEARCH("QTY:", G163) - 4)))} | M163: =K163 | N163: =L163 -> 0 | O163: {=IF(ISERROR(SEARCH("USD ", G163)), Raw [1]Data!S163, TRIM(MID(G163, SEARCH("USD ", G163)+4, SEARCH(" ", G163&" ", SEARCH("USD ", G163)+4) - SEARCH("USD ", G163) - 4)))} -> #NAME? | P163: =O163*M163 -> #NAME? | Q163: {=Raw [1]Data!P163} -> #NAME? | R163: {=Raw [1]Data!Q163} -> #NAME? | S163: {=Raw [1]Data!T163} -> #NAME? | T163: =S163/M163 -> #NAME? | U163: =IF(R163<>0, (S163/R163)*100, 0) -> #NAME? | V163: =IF(OR(E163=73239990,E163=73231000,E163=73239390),"Steel","Other") -> Other
A164: INNSA1 | B164: 2024-11-05 | C164: =YEAR(B164) -> 2024 | D164: 0301049751 | E164: 73231000 | F164: =LEFT(E164,2) -> 73 | G164: STEEL SCRUBBER 6PCS SET (OKS-4156) (QTY: 98400 NOS /USD 0.238 PER NOS) | H164: =IFERROR(LEFT(G164, FIND(" ",G164)), "") -> STEEL | I164: {=IFERROR(INDEX(_xlfn.TEXTSPLIT(E164," "),1), "")} -> 73231000 | J164: OKS-4156) | K164: {=IF(ISERROR(SEARCH("QTY:", G164)), IF(ISERROR(SEARCH("TOTAL ", G164)), Raw [1]Data!N164, TRIM(MID(G164, SEARCH("TOTAL ", G164)+6, SEARCH(" ", G164&" ", SEARCH("TOTAL ", G164)+6) - SEARCH("TOTAL ", G164) - 6))), TRIM(MID(G164, SEARCH("QTY:", G164)+4, SEARCH(" ", G164, SEARCH("QTY:", G164)+4) - SEARCH("QTY:", G164) - 4)))} | M164: =K164 | N164: =L164 -> 0 | O164: {=IF(ISERROR(SEARCH("USD ", G164)), Raw [1]Data!S164, TRIM(MID(G164, SEARCH("USD ", G164)+4, SEARCH(" ", G164&" ", SEARCH("USD ", G164)+4) - SEARCH("USD ", G164) - 4)))} -> 0.238 | P164: =O164*M164 -> #VALUE! | Q164: {=Raw [1]Data!P164} -> #NAME? | R164: {=Raw [1]Data!Q164} -> #NAME? | S164: {=Raw [1]Data!T164} -> #NAME? | T164: =S164/M164 -> #NAME? | U164: =IF(R164<>0, (S164/R164)*100, 0) -> #NAME? | V164: =IF(OR(E164=73239990,E164=73231000,E164=73239390),"Steel","Other") -> Other
A165: INNSA1 | B165: 2024-10-30 | C165: =YEAR(B165) -> 2024 | D165: 0301049751 | E165: 73239990 | F165: =LEFT(E165,2) -> 73 | G165: MILD STEEL MULTI FUNCTION CLOTH STAND (RYX-02-020) (QTY: 1232 NOS/CNY 101 PER NOS) | H165: =IFERROR(LEFT(G165, FIND(" ",G165)), "") -> MILD | I165: {=IFERROR(INDEX(_xlfn.TEXTSPLIT(E165," "),1), "")} -> 73239990 | K165: {=IF(ISERROR(SEARCH("QTY:", G165)), IF(ISERROR(SEARCH("TOTAL ", G165)), Raw [1]Data!N165, TRIM(MID(G165, SEARCH("TOTAL ", G165)+6, SEARCH(" ", G165&" ", SEARCH("TOTAL ", G165)+6) - SEARCH("TOTAL ", G165) - 6))), TRIM(MID(G165, SEARCH("QTY:", G165)+4, SEARCH(" ", G165, SEARCH("QTY:", G165)+4) - SEARCH("QTY:", G165) - 4)))} | M165: =K165 | N165: =L165 -> 0 | O165: {=IF(ISERROR(SEARCH("USD ", G165)), Raw [1]Data!S165, TRIM(MID(G165, SEARCH("USD ", G165)+4, SEARCH(" ", G165&" ", SEARCH("USD ", G165)+4) - SEARCH("USD ", G165) - 4)))} -> #NAME? | P165: =O165*M165 -> #NAME? | Q165: {=Raw [1]Data!P165} -> #NAME? | R165: {=Raw [1]Data!Q165} -> #NAME? | S165: {=Raw [1]Data!T165} -> #NAME? | T165: =S165/M165 -> #NAME? | U165: =IF(R165<>0, (S165/R165)*100, 0) -> #NAME? | V165: =IF(OR(E165=73239990,E165=73231000,E165=73239390),"Steel","Other") -> Other
A166: INNSA1 | B166: 2024-10-22 | C166: =YEAR(B166) -> 2024 | D166: 0301049751 | E166: 73239990 | F166: =LEFT(E166,2) -> 73 | G166: MILD STEEL MULTI FUNCTION CLOTH STAND (RYX-02-021A) (QTY: 3888 NOS/CNY 61.50 PER NOS) | H166: =IFERROR(LEFT(G166, FIND(" ",G166)), "") -> MILD | I166: {=IFERROR(INDEX(_xlfn.TEXTSPLIT(E166," "),1), "")} -> 73239990 | K166: {=IF(ISERROR(SEARCH("QTY:", G166)), IF(ISERROR(SEARCH("TOTAL ", G166)), Raw [1]Data!N166, TRIM(MID(G166, SEARCH("TOTAL ", G166)+6, SEARCH(" ", G166&" ", SEARCH("TOTAL ", G166)+6) - SEARCH("TOTAL ", G166) - 6))), TRIM(MID(G166, SEARCH("QTY:", G166)+4, SEARCH(" ", G166, SEARCH("QTY:", G166)+4) - SEARCH("QTY:", G166) - 4)))} | M166: =K166 | N166: =L166 -> 0 | O166: {=IF(ISERROR(SEARCH("USD ", G166)), Raw [1]Data!S166, TRIM(MID(G166, SEARCH("USD ", G166)+4, SEARCH(" ", G166&" ", SEARCH("USD ", G166)+4) - SEARCH("USD ", G166) - 4)))} -> #NAME? | P166: =O166*M166 -> #NAME? | Q166: {=Raw [1]Data!P166} -> #NAME? | R166: {=Raw [1]Data!Q166} -> #NAME? | S166: {=Raw [1]Data!T166} -> #NAME? | T166: =S166/M166 -> #NAME? | U166: =IF(R166<>0, (S166/R166)*100, 0) -> #NAME? | V166: =IF(OR(E166=73239990,E166=73231000,E166=73239390),"Steel","Other") -> Other
A167: INNSA1 | B167: 2024-10-18 | C167: =YEAR(B167) -> 2024 | D167: 0301049751 | E167: 73239990 | F167: =LEFT(E167,2) -> 73 | G167: HOUSEHOLD STEEL HOOK 3PCS SET (3888) (QTY: 30288 SET/USD 0.26PER SET) | H167: =IFERROR(LEFT(G167, FIND(" ",G167)), "") -> HOUSEHOLD | I167: {=IFERROR(INDEX(_xlfn.TEXTSPLIT(E167," "),1), "")} -> 73239990 | J167: 3888) | K167: {=IF(ISERROR(SEARCH("QTY:", G167)), IF(ISERROR(SEARCH("TOTAL ", G167)), Raw [1]Data!N167, TRIM(MID(G167, SEARCH("TOTAL ", G167)+6, SEARCH(" ", G167&" ", SEARCH("TOTAL ", G167)+6) - SEARCH("TOTAL ", G167) - 6))), TRIM(MID(G167, SEARCH("QTY:", G167)+4, SEARCH(" ", G167, SEARCH("QTY:", G167)+4) - SEARCH("QTY:", G167) - 4)))} | M167: =K167 | N167: =L167 -> 0 | O167: {=IF(ISERROR(SEARCH("USD ", G167)), Raw [1]Data!S167, TRIM(MID(G167, SEARCH("USD ", G167)+4, SEARCH(" ", G167&" ", SEARCH("USD ", G167)+4) - SEARCH("USD ", G167) - 4)))} -> 0.26PER | P167: =O167*M167 -> #VALUE! | Q167: {=Raw [1]Data!P167} -> #NAME? | R167: {=Raw [1]Data!Q167} -> #NAME? | S167: {=Raw [1]Data!T167} -> #NAME? | T167: =S167/M167 -> #NAME? | U167: =IF(R167<>0, (S167/R167)*100, 0) -> #NAME? | V167: =IF(OR(E167=73239990,E167=73231000,E167=73239390),"Steel","Other") -> Other
A168: INNSA1 | B168: 2024-10-16 | C168: =YEAR(B168) -> 2024 | D168: 0301049751 | E168: 73231000 | F168: =LEFT(E168,2) -> 73 | G168: STEEL SCRUBBER 2PCS SET (8001-2) (QTY: 168000 NOS /USD 0.148PER NOS) | H168: =IFERROR(LEFT(G168, FIND(" ",G168)), "") -> STEEL | I168: {=IFERROR(INDEX(_xlfn.TEXTSPLIT(E168," "),1), "")} -> 73231000 | J168: 8001-2) | K168: {=IF(ISERROR(SEARCH("QTY:", G168)), IF(ISERROR(SEARCH("TOTAL ", G168)), Raw [1]Data!N168, TRIM(MID(G168, SEARCH("TOTAL ", G168)+6, SEARCH(" ", G168&" ", SEARCH("TOTAL ", G168)+6) - SEARCH("TOTAL ", G168) - 6))), TRIM(MID(G168, SEARCH("QTY:", G168)+4, SEARCH(" ", G168, SEARCH("QTY:", G168)+4) - SEARCH("QTY:", G168) - 4)))} | M168: =K168 | N168: =L168 -> 0 | O168: {=IF(ISERROR(SEARCH("USD ", G168)), Raw [1]Data!S168, TRIM(MID(G168, SEARCH("USD ", G168)+4, SEARCH(" ", G168&" ", SEARCH("USD ", G168)+4) - SEARCH("USD ", G168) - 4)))} -> 0.148PER | P168: =O168*M168 -> #VALUE! | Q168: {=Raw [1]Data!P168} -> #NAME? | R168: {=Raw [1]Data!Q168} -> #NAME? | S168: {=Raw [1]Data!T168} -> #NAME? | T168: =S168/M168 -> #NAME? | U168: =IF(R168<>0, (S168/R168)*100, 0) -> #NAME? | V168: =IF(OR(E168=73239990,E168=73231000,E168=73239390),"Steel","Other") -> Other
A169: INNSA1 | B169: 2024-10-14 | C169: =YEAR(B169) -> 2024 | D169: 0301049751 | E169: 73231000 | F169: =LEFT(E169,2) -> 73 | G169: STEEL SCRUBBER 6PCS SET (OKS-4156) (QTY: 98400 SET/USD 0.238PER SET) | H169: =IFERROR(LEFT(G169, FIND(" ",G169)), "") -> STEEL | I169: {=IFERROR(INDEX(_xlfn.TEXTSPLIT(E169," "),1), "")} -> 73231000 | J169: OKS-4156) | K169: {=IF(ISERROR(SEARCH("QTY:", G169)), IF(ISERROR(SEARCH("TOTAL ", G169)), Raw [1]Data!N169, TRIM(MID(G169, SEARCH("TOTAL ", G169)+6, SEARCH(" ", G169&" ", SEARCH("TOTAL ", G169)+6) - SEARCH("TOTAL ", G169) - 6))), TRIM(MID(G169, SEARCH("QTY:", G169)+4, SEARCH(" ", G169, SEARCH("QTY:", G169)+4) - SEARCH("QTY:", G169) - 4)))} | M169: =K169 | N169: =L169 -> 0 | O169: {=IF(ISERROR(SEARCH("USD ", G169)), Raw [1]Data!S169, TRIM(MID(G169, SEARCH("USD ", G169)+4, SEARCH(" ", G169&" ", SEARCH("USD ", G169)+4) - SEARCH("USD ", G169) - 4)))} -> 0.238PER | P169: =O169*M169 -> #VALUE! | Q169: {=Raw [1]Data!P169} -> #NAME? | R169: {=Raw [1]Data!Q169} -> #NAME? | S169: {=Raw [1]Data!T169} -> #NAME? | T169: =S169/M169 -> #NAME? | U169: =IF(R169<>0, (S169/R169)*100, 0) -> #NAME? | V169: =IF(OR(E169=73239990,E169=73231000,E169=73239390),"Steel","Other") -> Other
A170: INNSA1 | B170: 2024-10-13 | C170: =YEAR(B170) -> 2024 | D170: 0301049751 | E170: 73239990 | F170: =LEFT(E170,2) -> 73 | G170: MILD STEEL MULTI FUNCTION CLOTH STAND (RYX-02-020) (QTY:1232NOS / CNY 101.00 PER NOS) | H170: =IFERROR(LEFT(G170, FIND(" ",G170)), "") -> MILD | I170: {=IFERROR(INDEX(_xlfn.TEXTSPLIT(E170," "),1), "")} -> 73239990 | K170: {=IF(ISERROR(SEARCH("QTY:", G170)), IF(ISERROR(SEARCH("TOTAL ", G170)), Raw [1]Data!N170, TRIM(MID(G170, SEARCH("TOTAL ", G170)+6, SEARCH(" ", G170&" ", SEARCH("TOTAL ", G170)+6) - SEARCH("TOTAL ", G170) - 6))), TRIM(MID(G170, SEARCH("QTY:", G170)+4, SEARCH(" ", G170, SEARCH("QTY:", G170)+4) - SEARCH("QTY:", G170) - 4)))} -> 1232NOS | M170: =K170 -> 1232NOS | N170: =L170 -> 0 | O170: {=IF(ISERROR(SEARCH("USD ", G170)), Raw [1]Data!S170, TRIM(MID(G170, SEARCH("USD ", G170)+4, SEARCH(" ", G170&" ", SEARCH("USD ", G170)+4) - SEARCH("USD ", G170) - 4)))} -> #NAME? | P170: =O170*M170 -> #NAME? | Q170: {=Raw [1]Data!P170} -> #NAME? | R170: {=Raw [1]Data!Q170} -> #NAME? | S170: {=Raw [1]Data!T170} -> #NAME? | T170: =S170/M170 -> #NAME? | U170: =IF(R170<>0, (S170/R170)*100, 0) -> #NAME? | V170: =IF(OR(E170=73239990,E170=73231000,E170=73239390),"Steel","Other") -> Other
A171: INNSA1 | B171: 2024-10-08 | C171: =YEAR(B171) -> 2024 | D171: 0301049751 | E171: 73239990 | F171: =LEFT(E171,2) -> 73 | G171: HOUSEHOLD STEEL HOOK 2PCS SET (2758) (QTY: 2400 SET/USD 0.265 PER SET) | H171: =IFERROR(LEFT(G171, FIND(" ",G171)), "") -> HOUSEHOLD | I171: {=IFERROR(INDEX(_xlfn.TEXTSPLIT(E171," "),1), "")} -> 73239990 | J171: 2758) | K171: {=IF(ISERROR(SEARCH("QTY:", G171)), IF(ISERROR(SEARCH("TOTAL ", G171)), Raw [1]Data!N171, TRIM(MID(G171, SEARCH("TOTAL ", G171)+6, SEARCH(" ", G171&" ", SEARCH("TOTAL ", G171)+6) - SEARCH("TOTAL ", G171) - 6))), TRIM(MID(G171, SEARCH("QTY:", G171)+4, SEARCH(" ", G171, SEARCH("QTY:", G171)+4) - SEARCH("QTY:", G171) - 4)))} | M171: =K171 | N171: =L171 -> 0 | O171: {=IF(ISERROR(SEARCH("USD ", G171)), Raw [1]Data!S171, TRIM(MID(G171, SEARCH("USD ", G171)+4, SEARCH(" ", G171&" ", SEARCH("USD ", G171)+4) - SEARCH("USD ", G171) - 4)))} -> 0.265 | P171: =O171*M171 -> #VALUE! | Q171: {=Raw [1]Data!P171} -> #NAME? | R171: {=Raw [1]Data!Q171} -> #NAME? | S171: {=Raw [1]Data!T171} -> #NAME? | T171: =S171/M171 -> #NAME? | U171: =IF(R171<>0, (S171/R171)*100, 0) -> #NAME? | V171: =IF(OR(E171=73239990,E171=73231000,E171=73239390),"Steel","Other") -> Other
A172: INNSA1 | B172: 2024-10-05 | C172: =YEAR(B172) -> 2024 | D172: 0301049751 | E172: 73239990 | F172: =LEFT(E172,2) -> 73 | G172: RYX-02-020 MILD STEEL MULTI FUNCTION CLOTH STAND (QTY :1232NUM/CNY 101.00 PER NUM) | H172: =IFERROR(LEFT(G172, FIND(" ",G172)), "") -> RYX-02-020 | I172: {=IFERROR(INDEX(_xlfn.TEXTSPLIT(E172," "),1), "")} -> 73239990 | K172: {=IF(ISERROR(SEARCH("QTY:", G172)), IF(ISERROR(SEARCH("TOTAL ", G172)), Raw [1]Data!N172, TRIM(MID(G172, SEARCH("TOTAL ", G172)+6, SEARCH(" ", G172&" ", SEARCH("TOTAL ", G172)+6) - SEARCH("TOTAL ", G172) - 6))), TRIM(MID(G172, SEARCH("QTY:", G172)+4, SEARCH(" ", G172, SEARCH("QTY:", G172)+4) - SEARCH("QTY:", G172) - 4)))} -> #NAME? | M172: =K172 -> #NAME? | N172: =L172 -> 0 | O172: {=IF(ISERROR(SEARCH("USD ", G172)), Raw [1]Data!S172, TRIM(MID(G172, SEARCH("USD ", G172)+4, SEARCH(" ", G172&" ", SEARCH("USD ", G172)+4) - SEARCH("USD ", G172) - 4)))} -> #NAME? | P172: =O172*M172 -> #NAME? | Q172: {=Raw [1]Data!P172} -> #NAME? | R172: {=Raw [1]Data!Q172} -> #NAME? | S172: {=Raw [1]Data!T172} -> #NAME? | T172: =S172/M172 -> #NAME? | U172: =IF(R172<>0, (S172/R172)*100, 0) -> #NAME? | V172: =IF(OR(E172=73239990,E172=73231000,E172=73239390),"Steel","Other") -> Other
